<?xml version="1.0"?>
<robot name="scara">



<!--  Defining only the "color" parameter of "material"-->
<material name="blue">
    <color rgba="0 0 1 1"/>
  </material>
  <material name="red">
    <color rgba="1 0 0 1"/>
  </material>
  <material name="green">
    <color rgba="0 1 0 1"/>
  </material>
      <material name="yellow">
    <color rgba="1 1 0 1"/>
  </material>


<!-- Creating the base_link and base_link son and visual joint-->
  <link name="base_link">
    <visual>
      <geometry>
        <cylinder length="1" radius="0.5"/>
      </geometry>
       <origin rpy="0 0 0" xyz="0 0 0.5"/>
      <material name="yellow"/>
    </visual>
  </link>

   <link name="base_link_son">
    <visual>
      <geometry>
        <cylinder length="1" radius="0.5"/>
      </geometry>
       <origin rpy="0 0 0" xyz="0 0 -0.5"/>
      <material name="blue"/>
    </visual>
  </link>-->

  <joint name="base_link_to_base_link_son" type="fixed">
    <parent link="base_link"/>
    <child link="base_link_son"/>
    <origin xyz="0 0 2"/>
  </joint>




<!-- Creating the link1 and continuous joint-->
  <link name="link1">
    <visual>
      <geometry>
        <box size="4 1 1"/>
      </geometry>
      <origin rpy="1.57075 0 0" xyz="2 0 -0.5"/>
      <material name="blue"/>
    </visual>
  </link>


  <joint name="joint1__base_link_to_link1" type="continuous">
    <parent link="base_link"/>
    <child link="link1"/>
      <axis xyz="0 0 1"/>
    <origin xyz="0 0 2"/>
  </joint>



  <!-- Creating the link2 and continuous joint-->
  <link name="link2">
    <visual>
      <geometry>
        <box size="4 1 1"/>
      </geometry>
      <origin rpy="1.57075 0 0" xyz="2 0 -0.5"/>
      <material name="red"/>
    </visual>
  </link>

  <joint name="joint2__link1_to_link2" type="continuous">
    <parent link="link1"/>
    <child link="link2"/>
      <axis xyz="0 0 1"/>
    <origin xyz="4 0 0"/>
  </joint>



    <!-- Creating the link1_link2 visual joint-->
   <link name="link1_link2_base">
    <visual>
      <geometry>
        <cylinder length="1" radius="0.5"/>
      </geometry>
      <origin rpy="0 0 0" xyz="0 0 -0.5"/>
      <material name="red"/>
    </visual>
  </link>


   <joint name="link1_to_link2" type="fixed">
    <parent link="link1"/>
    <child link="link1_link2_base"/>
    <origin xyz="4 0 0"/>
  </joint>


    <!-- Creating the link2_grip_base visual joint-->

  <link name="grip_base">
    <visual>
      <geometry>
         <cylinder length="1" radius="0.5"/>
      </geometry>
      <origin rpy="0 0 0" xyz="0 0 -0.5"/>
      <material name="red"/>
    </visual>
  </link>


  <joint name="link2_to_grip_base" type="fixed">
    <parent link="link2"/>
    <child link="grip_base"/>
    <origin xyz="4 0 0"/>
  </joint>




    <!-- Creating the grip link and prismatic joint-->
 <link name="grip_link">
    <visual>
      <geometry>
         <cylinder length="2" radius="0.15"/>
      </geometry>
      <origin rpy="0 0 0" xyz="0 0 1"/>
      <material name="green"/>
    </visual>
  </link>


  <joint name="joint3__grip_base_to_grip_link" type="prismatic">
    <parent link="grip_base"/>
    <child link="grip_link"/>
    <limit effort="1000.0" lower="-1.5" upper="1.0" velocity="0.5"/>
    <axis xyz="0 0 1"/>
    <origin xyz="0 0 -1"/>
  </joint>

</robot>